Workbook
Name CL: 'RELEVANCIA-PUNTAJE'!$B$2
Name L: 'RELEVANCIA-PUNTAJE'!$C$2
Name ML: 'RELEVANCIA-PUNTAJE'!$D$2
Name MR: 'RELEVANCIA-PUNTAJE'!$A$3
Name MR_CL: 'RELEVANCIA-PUNTAJE'!$B$3
Name MR_L: 'RELEVANCIA-PUNTAJE'!$C$3
Name MR_ML: 'RELEVANCIA-PUNTAJE'!$D$3
Name MR_NL: 'RELEVANCIA-PUNTAJE'!$E$3
Name MR_PL: 'RELEVANCIA-PUNTAJE'!#REF!
Name MR_TL: 'RELEVANCIA-PUNTAJE'!$B$3
Name NL: 'RELEVANCIA-PUNTAJE'!$E$2
Name PL: 'RELEVANCIA-PUNTAJE'!#REF!
Name PR: 'RELEVANCIA-PUNTAJE'!$A$5
Name PR_ML: 'RELEVANCIA-PUNTAJE'!$D$5
Name PR_NL: 'RELEVANCIA-PUNTAJE'!$E$5
Name PR_PL: 'RELEVANCIA-PUNTAJE'!#REF!
Name PR_TL: 'RELEVANCIA-PUNTAJE'!$B$5
Name RE: 'RELEVANCIA-PUNTAJE'!$A$4
Name RE_ML: 'RELEVANCIA-PUNTAJE'!$D$4
Name RE_NL: 'RELEVANCIA-PUNTAJE'!$E$4
Name RE_PL: 'RELEVANCIA-PUNTAJE'!#REF!
Name RE_TL: 'RELEVANCIA-PUNTAJE'!$B$4
Name TL: 'RELEVANCIA-PUNTAJE'!$B$2

Sheet RUBRICA
A1: Indicador de Evaluación | B1: Categorías de Respuesta | F1: Ponderación del Indicador de Evaluación
B2: Completamente Logrado (100%) | C2: Logrado (60%) | D2: Logro incipiente | E2: No logrado
D3: -0.3 | E3: 0
A4: 1. Implementa una metodología que permite el logro de los objetivos propuestos, de acuerdo a los estándares de la disciplina. | B4: Describe la metodología utilizada de acuerdo a los estándares de la disciplina, alcanzando todos los objetivos propuestos para el proyecto. | C4: Describe la metodología utilizada de acuerdo a los estándares de la disciplina, pero cumple parcialmente los objetivos propuestos para el proyecto. | D4: Describe la metodología utilizada cumpliendo parcialmente con los estándares de la disciplina y con los objetivos propuestos para el proyecto. | E4: Describe la metodología utilizada sin cumplir los estándares de la disciplina ni los objetivos propuestos para el proyecto. | F4: 10
A5: 2. Genera evidencias que dan cuenta del cumplimiento del Proyecto CAPSTONE, en relación a documentación, programación y almacenamiento de datos, de acuerdo a lo planificado por el equipo y que cumpla con estándares de desarrollo de la industria | B5: Genera evidencias que dan cuenta del cumplimiento del Proyecto CAPSTONE, en relación a documentación, programación y almacenamiento de datos, de acuerdo a lo planificado por el equipo y que cumpla con estándares de desarrollo de la industria | C5: Genera evidencias que dan cuenta del cumplimiento del Proyecto CAPSTONE, en relación a documentación, programación y almacenamiento de datos, de acuerdo a lo planificado por el equipo y no cumplen con estándares de desarrollo de la industria | D5: Genera evidencias pero ellas no dan cuenta del cumplimiento del Proyecto CAPSTONE, en relación a documentación, programación y almacenamiento de datos, de acuerdo a lo planificado por el equipo, pero si cumple con estándares de desarrollo de la industria | E5: Genera evidencias pero ellas no dan cuenta del cumplimiento del Proyecto CAPSTONE, en relación a documentación, programación y almacenamiento de datos, de acuerdo a lo planificado por el equipo, y no cumplen con estándares de desarrollo de la industria | F5: 20
A6: 3. Relaciona el Proyecto APT con sus intereses profesionales. * | B6: Menciona los intereses profesionales y explica con claridad cómo estos se ven reflejados en el proyecto. | C6: Menciona los intereses profesionales, pero no queda completamente clara su conexión con el proyecto. | D6: Menciona los intereses profesionales sin conectarlos con el proyecto. | E6: No menciona los intereses profesionales. | F6: 5
A7: 4. Relaciona el Proyecto APT con las competencias del perfil de egreso de su Plan de Estudio. | B7: Describe una relación coherente entre el proyecto y el perfil de egreso del plan de estudio, especificando cómo debe utilizar distintas competencias para desarrollar su Proyecto APT. | C7: Describe una relación coherente entre el proyecto y el perfil de egreso del plan de estudio, pero no especifica cómo debe utilizar distintas competencias para desarrollar su Proyecto APT. | D7: Describe una relación que tiene elementos pero que no son coherentes entre el proyecto y el perfil de egreso del plan de estudio. | E7: Describe una relación sin coherencia entre el proyecto y el perfil de egreso del plan de estudio o no relaciona el proyecto con el perfil de egreso. | F7: 5
A8: 5. Utiliza de manera precisa el lenguaje técnico en los entregables de acuerdo con lo requerido por la disciplina. | B8: Utiliza lenguaje técnico de su disciplina en todos los entregables de avance del proyecto. | C8: Utiliza lenguaje técnico de su disciplina en la mayoría de los entregables de avance del proyecto | D8: Utiliza lenguaje técnico de su disciplina en la menos de la mitad de los entregables de avance del proyecto | E8: No utiliza lenguaje técnico de su disciplina en los entregables de avance del proyecto. | F8: 5
A9: 6. Utiliza correctamente las reglas de redacción, ortografía (literal, puntual, acentual) y las normas para citas y referencias. | B9: El texto cumple con las reglas ortografía y de redacción en todos sus apartados y utiliza correctamente todas las normas de citación y referencias. | C9: El texto presenta de 1 a 5 errores de ortografía, redacción o en las citas y referencias del informe. | D9: El texto presenta de 6 a 10 errores de ortografía, redacción o en las citas y referencias del informe. | E9: El texto presenta más de 10 errores de ortografía, redacción o en las citas y referencias del informe. | F9: 5
A10: 7. Entrega la documentación y evidencias requerida por la asignatura de acuerdo a la estrucutra y nombres solicitados, guardando todas las evidencias de avances en Git | B10: Entrega la documentación y evidencias requeridas por la asignatura de acuerdo a la estrucutra y nombres solicitados, guardando todas las evidencias de avances en Git | C10: Entrega la documentación y evidencias requeridas por la asignatura de acuerdo a la estrucutra y nombres solicitados, guardando algunas de las evidencias de avances en Git | D10: Entrega la documentación y evidencias requeridas por la asignatura sin una la estrucutra y nombres solicitados, guardando algunas de las evidencias de avances en Git | E10: No entrega a través de Git la documentación y evidencias de avance requeridas por la asignatura | F10: 15
A11: 8. Expone el tema utilizando un lenguaje técnico disciplinar al presentar la propuesta y responde evidenciando un manejo de la información. * | B11: Expone el tema utilizando un lenguaje técnico disciplinar al presentar la propuesta y responde evidenciando un manejo de la información en todo momento | C11: Expone el tema utilizando un lenguaje técnico disciplinar al presentar la propuesta y responde evidenciando un manejo de la información la mayoría del tiempo. | D11: Expone el tema utilizando un lenguaje técnico disciplinar al presentar la propuesta y responde evidenciando un manejo de la información la mitad del tiempo. | E11: Expone el tema utilizando un lenguaje técnico disciplinar al presentar la propuesta y responde evidenciando un manejo de la información en menos de la mitad del tiempo. | F11: 10
A12: 9.-Generan evidencias claras dentro del repositorio del aporte de cada uno de los integrantes del equipo que permitan identificar la equidad en el trabajo y la participación de cada estudiante. | B12: Generan evidencias dentro del repositorio del proyecto del aporte de cada uno de los integrantes del equipo que permitan identificar la equidad en el trabajo y la participación de cada estudiante | C12: Generan evidencias dentro del repositorio del proyecto del aporte de cada uno de los integrantes del equipo pero la evidencia no demuestra una equidad en la participación de cada estudiante | D12: Generan evidencias dentro del repositorio del proyecto del aporte de cada uno de los integrantes del equipo pero la evidencia no demuestra la participación de algunos(s) participante(s) del equipo | E12: No generan evidencias dentro del repositorio del proyecto del aporte de cada uno de los integrantes del equipo por lo que no se permite identificar la equidad en el trabajo y la participación de cada estudiante | F12: 15
A13: 10. Colaboración y trabajo en equipo * | B13: El estudiante realiza un excelente trabajo en equipo, fomentando un ambiente positivo, siendo participativo con su equipo en las sesiones presenciales de la asignatura y participando de manera equitativa en la presentación del caso | C13: El estudiante realiza un buen trabajo en equipo, fomentando un ambiente positivo, siendo participativo con su equipo en las sesiones presenciales de la asignatura, pero no demuestra una participación de manera equitativa en la presentación del caso | D13: El estudiante realiza un trabajo deficiente con el equipo, fomentando un ambiente positivo pero no demuestra ser participativo con su equipo en las sesiones presenciales de la asignatura o se ausenta constantemente y/o no demuestra una participación de manera equitativa en la presentación del caso | E13: El estudiante realiza un mal trabajo con el equipo no fomentando un ambiente positivo, no demuestra ser participativo con su equipo en las sesiones presenciales de la asignatura o se ausenta constantemente y no demuestra una participación de manera equitativa en la presentación del caso | F13: 10

Sheet EVALUACION1
C2: 0.75 | D2: 0.25 | E2: 1
B3: INTEGRANTES | C3: GRUPAL | D3: INDIVIDUAL
A4: 1 | B4: Ociel Escobar | C4: =IF(B4="","",IF(EVALUACION1!$C$21="","",EVALUACION1!$C$21)) | D4: =IF(B4="","",IF($C$32="","",$C$32)) | E4: =IF(OR(B4="",C4="",D4=""),"",C4*C$2+D4*D$2)
A5: 2 | B5: Sebastian Torres | C5: =IF(B5="","",IF(EVALUACION1!$C$21="","",EVALUACION1!$C$21)) | D5: =IF(B5="","",IF($C$44="","",$C$44)) | E5: =IF(OR(B5="",C5="",D5=""),"",C5*C$2+D5*D$2)
A6: 3 | C6: =IF(B6="","",IF(EVALUACION1!$C$21="","",EVALUACION1!$C$21)) | D6: =IF(B6="","",IF($C$55="","",$C$55)) | E6: =IF(OR(B6="",C6="",D6=""),"",C6*C$2+D6*D$2)
B8: Evaluación pendiente del docente
B9: Proyecto PID R2 · Informática · 007V · Ernesto Velasquez
A11: GRUPAL | C11: Nivel de Logro | D11: NIVELES DE LOGRO Y PUNTAJES
B12: Aspectos a Evaluar | D12: Completamente logrado | F12: Logrado | H12: Logro Incipiente | J12: No logrado
B13: =RUBRICA!A4 -> 1. Implementa una metodología que permite el logro de los objetivos propuestos, de acuerdo a los estándares de la disciplina. | D13: =IF($C13=CL,"X","") | E13: =IF(D13="X",100*0.1,"") | F13: =IF($C13=L,"X","") | G13: =IF(F13="X",60*0.1,"") | H13: =IF($C13=ML,"X","") | I13: =IF(H13="X",30*0.1,"") | J13: =IF($C13=NL,"X","") | K13: =IF(J13="X",0*0.1,"")
B14: =RUBRICA!A5 -> 2. Genera evidencias que dan cuenta del cumplimiento del Proyecto CAPSTONE, en relación a documentación, programación y almacenamiento de datos, de acuerdo a lo planificado por el equipo y que cumpla con estándares de desarrollo de la industria | D14: =IF($C14=CL,"X","") | E14: =IF(D14="X",100*0.2,"") | F14: =IF($C14=L,"X","") | G14: =IF(F14="X",60*0.2,"") | H14: =IF($C14=ML,"X","") | I14: =IF(H14="X",30*0.2,"") | J14: =IF($C14=NL,"X","") | K14: =IF(J14="X",0*0.2,"")
B15: =RUBRICA!A7 -> 4. Relaciona el Proyecto APT con las competencias del perfil de egreso de su Plan de Estudio. | D15: =IF($C15=CL,"X","") | E15: =IF(D15="X",100*0.05,"") | F15: =IF($C15=L,"X","") | G15: =IF(F15="X",60*0.05,"") | H15: =IF($C15=ML,"X","") | I15: =IF(H15="X",30*0.05,"") | J15: =IF($C15=NL,"X","") | K15: =IF(J15="X",0*0.05,"")
B16: =RUBRICA!A8 -> 5. Utiliza de manera precisa el lenguaje técnico en los entregables de acuerdo con lo requerido por la disciplina. | D16: =IF($C16=CL,"X","") | E16: =IF(D16="X",100*0.05,"") | F16: =IF($C16=L,"X","") | G16: =IF(F16="X",60*0.05,"") | H16: =IF($C16=ML,"X","") | I16: =IF(H16="X",30*0.05,"") | J16: =IF($C16=NL,"X","") | K16: =IF(J16="X",0*0.05,"")
B17: =RUBRICA!A9 -> 6. Utiliza correctamente las reglas de redacción, ortografía (literal, puntual, acentual) y las normas para citas y referencias. | D17: =IF($C17=CL,"X","") | E17: =IF(D17="X",100*0.05,"") | F17: =IF($C17=L,"X","") | G17: =IF(F17="X",60*0.05,"") | H17: =IF($C17=ML,"X","") | I17: =IF(H17="X",30*0.05,"") | J17: =IF($C17=NL,"X","") | K17: =IF(J17="X",0*0.05,"")
B18: =RUBRICA!A10 -> 7. Entrega la documentación y evidencias requerida por la asignatura de acuerdo a la estrucutra y nombres solicitados, guardando todas las evidencias de avances en Git | D18: =IF($C18=CL,"X","") | E18: =IF(D18="X",100*0.15,"") | F18: =IF($C18=L,"X","") | G18: =IF(F18="X",60*0.15,"") | H18: =IF($C18=ML,"X","") | I18: =IF(H18="X",30*0.15,"") | J18: =IF($C18=NL,"X","") | K18: =IF(J18="X",0*0.15,"")
B19: =RUBRICA!A12 -> 9.-Generan evidencias claras dentro del repositorio del aporte de cada uno de los integrantes del equipo que permitan identificar la equidad en el trabajo y la participación de cada estudiante. | D19: =IF($C19=CL,"X","") | E19: =IF(D19="X",100*0.15,"") | F19: =IF($C19=L,"X","") | G19: =IF(F19="X",60*0.15,"") | H19: =IF($C19=ML,"X","") | I19: =IF(H19="X",30*0.15,"") | J19: =IF($C19=NL,"X","") | K19: =IF(J19="X",0*0.15,"")
B20: Puntaje | C20: =IF(COUNTA(C13:C19)<7,"",E20+G20+I20+K20) | E20: =IF(COUNTA(C13:C19)<7,"",SUM(E13:E19)) | G20: =IF(COUNTA(C13:C19)<7,"",SUM(G13:G19)) | I20: =IF(COUNTA(C13:C19)<7,"",SUM(I13:I19)) | K20: =IF(COUNTA(C13:C19)<7,"",SUM(K13:K19))
B21: Nota | C21: =IF(C20="","",VLOOKUP(C20,ESCALA_IEP!A1:B152,2,FALSE))
A24: INDIVIDUAL | B24: NOMBRE ALUMNO | C24: =IF($B$4="","",$B$4) -> Ociel Escobar
B26: Capacidad de Trabajo en Equipo | C26: Nivel de Logro | D26: NIVELES DE LOGRO Y PUNTAJES
B27: Aspectos a Evaluar | D27: Completamente logrado | F27: Logrado | H27: Logro Incipiente | J27: No logrado
B28: =RUBRICA!A6 -> 3. Relaciona el Proyecto APT con sus intereses profesionales. * | D28: =IF($C28=CL,"X","") | E28: =IF(D28="X",100*0.05,"") | F28: =IF($C28=L,"X","") | G28: =IF(F28="X",60*0.05,"") | H28: =IF($C28=ML,"X","") | I28: =IF(H28="X",30*0.05,"") | J28: =IF($C28=NL,"X","") | K28: =IF(J28="X",0*0.05,"")
B29: =RUBRICA!A11 -> 8. Expone el tema utilizando un lenguaje técnico disciplinar al presentar la propuesta y responde evidenciando un manejo de la información. * | D29: =IF($C29=CL,"X","") | E29: =IF(D29="X",100*0.1,"") | F29: =IF($C29=L,"X","") | G29: =IF(F29="X",60*0.1,"") | H29: =IF($C29=ML,"X","") | I29: =IF(H29="X",30*0.1,"") | J29: =IF($C29=NL,"X","") | K29: =IF(J29="X",0*0.1,"")
B30: =RUBRICA!A13 -> 10. Colaboración y trabajo en equipo * | D30: =IF($C30=CL,"X","") | E30: =IF(D30="X",100*0.1,"") | F30: =IF($C30=L,"X","") | G30: =IF(F30="X",60*0.1,"") | H30: =IF($C30=ML,"X","") | I30: =IF(H30="X",30*0.1,"") | J30: =IF($C30=NL,"X","") | K30: =IF(J30="X",0*0.1,"")
B31: PUNTAJE | C31: =IF(COUNTA(C28:C30)<3,"",E31+G31+I31+K31) | E31: =IF(COUNTA(C28:C30)<3,"",SUM(E28:E30)) | G31: =IF(COUNTA(C28:C30)<3,"",SUM(G28:G30)) | I31: =IF(COUNTA(C28:C30)<3,"",SUM(I28:I30)) | K31: =IF(COUNTA(C28:C30)<3,"",SUM(K28:K30))
B32: Nota | C32: =IF(C31="","",VLOOKUP(C31,ESCALA_TRAB_EQUIP!A1:B52,2,FALSE))
A36: INDIVIDUAL | B36: NOMBRE ALUMNO | C36: =IF($B$5="","",$B$5) -> Sebastian Torres
B38: Capacidad de Trabajo en Equipo | C38: Nivel de Logro | D38: NIVELES DE LOGRO Y PUNTAJES
B39: Aspectos a Evaluar | D39: Completamente logrado | F39: Logrado | H39: Logro Incipiente | J39: No logrado
B40: =RUBRICA!A6 -> 3. Relaciona el Proyecto APT con sus intereses profesionales. * | D40: =IF($C40=CL,"X","") | E40: =IF(D40="X",100*0.05,"") | F40: =IF($C40=L,"X","") | G40: =IF(F40="X",60*0.05,"") | H40: =IF($C40=ML,"X","") | I40: =IF(H40="X",30*0.05,"") | J40: =IF($C40=NL,"X","") | K40: =IF(J40="X",0*0.05,"")
B41: =RUBRICA!A11 -> 8. Expone el tema utilizando un lenguaje técnico disciplinar al presentar la propuesta y responde evidenciando un manejo de la información. * | D41: =IF($C41=CL,"X","") | E41: =IF(D41="X",100*0.1,"") | F41: =IF($C41=L,"X","") | G41: =IF(F41="X",60*0.1,"") | H41: =IF($C41=ML,"X","") | I41: =IF(H41="X",30*0.1,"") | J41: =IF($C41=NL,"X","") | K41: =IF(J41="X",0*0.1,"")
B42: =RUBRICA!A13 -> 10. Colaboración y trabajo en equipo * | D42: =IF($C42=CL,"X","") | E42: =IF(D42="X",100*0.1,"") | F42: =IF($C42=L,"X","") | G42: =IF(F42="X",60*0.1,"") | H42: =IF($C42=ML,"X","") | I42: =IF(H42="X",30*0.1,"") | J42: =IF($C42=NL,"X","") | K42: =IF(J42="X",0*0.1,"")
B43: PUNTAJE | C43: =IF(COUNTA(C40:C42)<3,"",E43+G43+I43+K43) | E43: =IF(COUNTA(C40:C42)<3,"",SUM(E40:E42)) | G43: =IF(COUNTA(C40:C42)<3,"",SUM(G40:G42)) | I43: =IF(COUNTA(C40:C42)<3,"",SUM(I40:I42)) | K43: =IF(COUNTA(C40:C42)<3,"",SUM(K40:K42))
B44: Nota | C44: =IF(C43="","",VLOOKUP(C43,ESCALA_TRAB_EQUIP!A1:B52,2,FALSE))
A47: INDIVIDUAL | B47: NOMBRE ALUMNO | C47: =IF($B$6="","No aplica - equipo de dos integrantes",$B$6) -> No aplica - equipo de dos integrantes
B49: Capacidad de Trabajo en Equipo | C49: Nivel de Logro | D49: NIVELES DE LOGRO Y PUNTAJES
B50: Aspectos a Evaluar | D50: Completamente logrado | F50: Logrado | H50: Logro Incipiente | J50: No logrado
B51: =RUBRICA!A6 -> 3. Relaciona el Proyecto APT con sus intereses profesionales. * | D51: =IF($C51=CL,"X","") | E51: =IF(D51="X",100*0.05,"") | F51: =IF($C51=L,"X","") | G51: =IF(F51="X",60*0.05,"") | H51: =IF($C51=ML,"X","") | I51: =IF(H51="X",30*0.05,"") | J51: =IF($C51=NL,"X","") | K51: =IF(J51="X",0*0.05,"")
B52: =RUBRICA!A11 -> 8. Expone el tema utilizando un lenguaje técnico disciplinar al presentar la propuesta y responde evidenciando un manejo de la información. * | D52: =IF($C52=CL,"X","") | E52: =IF(D52="X",100*0.1,"") | F52: =IF($C52=L,"X","") | G52: =IF(F52="X",60*0.1,"") | H52: =IF($C52=ML,"X","") | I52: =IF(H52="X",30*0.1,"") | J52: =IF($C52=NL,"X","") | K52: =IF(J52="X",0*0.1,"")
B53: =RUBRICA!A13 -> 10. Colaboración y trabajo en equipo * | D53: =IF($C53=CL,"X","") | E53: =IF(D53="X",100*0.1,"") | F53: =IF($C53=L,"X","") | G53: =IF(F53="X",60*0.1,"") | H53: =IF($C53=ML,"X","") | I53: =IF(H53="X",30*0.1,"") | J53: =IF($C53=NL,"X","") | K53: =IF(J53="X",0*0.1,"")
...

Sheet ESCALA_IEP
A1: Puntaje | B1: Nota
A2: 0 | B2: 1
A3: 0.5 | B3: 1
A4: 1 | B4: 1.1
A5: 1.5 | B5: 1.1
A6: 2 | B6: 1.1
A7: 2.5 | B7: 1.2
A8: 3 | B8: 1.2
A9: 3.5 | B9: 1.2
A10: 4 | B10: 1.3
A11: 4.5 | B11: 1.3
A12: 5 | B12: 1.3
A13: 5.5 | B13: 1.4
... A152: 75 | B152: 7

Sheet ESCALA_PRESENTACION
A1: PUNTOS | B1: NOTA
A2: 0 | B2: 1
A3: 1 | B3: 1.1
A4: 2 | B4: 1.2
A5: 3 | B5: 1.3
A6: 4 | B6: 1.4
A7: 5 | B7: 1.5
A8: 6 | B8: 1.6
A9: 7 | B9: 1.7
A10: 8 | B10: 1.8
A11: 9 | B11: 1.9
A12: 10 | B12: 2
A13: 11 | B13: 2.1
... A54: 52 | B54: 7

Sheet ESCALA_TRAB_EQUIP
A1: Puntaje | B1: Nota
A2: 0 | B2: 1
A3: 0.5 | B3: 1.1
A4: 1 | B4: 1.2
A5: 1.5 | B5: 1.3
A6: 2 | B6: 1.4
A7: 2.5 | B7: 1.5
A8: 3 | B8: 1.6
A9: 3.5 | B9: 1.7
A10: 4 | B10: 1.8
A11: 4.5 | B11: 1.9
A12: 5 | B12: 2
A13: 5.5 | B13: 2.1
... A52: 25 | B52: 7

Sheet RELEVANCIA-PUNTAJE
A1: Relevancia | B1: Puntaje
B2: Completamente logrado | C2: Logrado | D2: Logro incipiente | E2: No logrado
A3: Muy Relevante | B3: 4 | C3: 3 | D3: 2 | E3: 0

Sheet Evidencias del equipo
A1: Evidencias del equipo para evaluación
A2: Ociel Escobar y Sebastian Torres · Ingeniería en Informática · Sección 007V
A3: Docente Ernesto Velasquez · Corte documental 21-10-2026
A4: Las calificaciones y niveles están reservados al docente. No se asignan notas al completar esta planilla.
A6: Aspecto | B6: Evidencia disponible | C6: Ubicación desde Fase 2 | D6: Estado real | E6: Pendiente de completar o demostrar | F6: Responsable
A7: Identificación | B7: Ociel Escobar y Sebastian Torres | C7: Ingeniería en Informática · 007V | D7: Confirmado | E7: Docente Ernesto Velasquez | F7: Equipo
A8: Metodología | B8: Revisión incremental; HU, RNF, tareas y pruebas relacionadas | C8: Evidencias de documentación/Product Backlog.xlsx y Sprint Backlog.xlsx | D8: Documentado | E8: Fechas y acuerdos de sprints por confirmar; no acreditar ceremonias sin acta | F8: Equipo
A9: Programación | B9: JSON de 39 nodos; 14 funciones JS; revisión de 45 conexiones | C9: Evidencias de sistema/Aplicación/01_Flujo_actual_PID_R2.json | D9: Disponible | E9: Validación integrada de n8n pendiente | F9: Equipo
A10: Datos | B10: Nueve nodos SQL, siete objetos consultados, contratos observados | C10: Evidencias de sistema/Base de datos/ | D10: Fuente disponible | E10: Completar registros SQL con resultados auténticos; sin DDL confirmado | F10: Ociel Escobar (propuesta)
A11: Pruebas | B11: 12 casos locales: 7 aprobados y 5 fallidos; 18 de integración pendientes | C11: Evidencias de documentación/Pruebas.xlsx; Evidencias de sistema/Aplicación/Pruebas locales/Resultados/ | D11: Parcial | E11: Corregir fechas, término, mes siguiente, plazo final y simulación | F11: Equipo
A12: Lenguaje y redacción | B12: UML, modelo lógico, criterios verificables y referencias internas | C12: Evidencias de documentación/ y guías grupales completadas | D12: Preparado | E12: Revisión conjunta y evaluación de calidad por el docente | F12: Equipo
A13: Perfil de egreso | B13: Aplicación técnica de análisis, datos, integración, programación y calidad | C13: Informe final, tabla de competencias | D13: Relación técnica descrita | E13: Cotejar denominaciones con perfil oficial de la carrera | F13: Equipo
A14: Intereses profesionales | B14: Ociel: análisis de datos, BD y Power BI. Sebastian: área específica aún sin definir | C14: Informe final, intereses y proyecciones | D14: Declaración parcial | E14: Power BI es proyección, no funcionalidad implementada; completar reflexión de Sebastian | F14: Equipo
A15: Estructura de entrega y Git | B15: Archivos organizados en Fase 2; historial anterior observable | C15: Fase 2/ y repositorio Capstone.OE.ST | D15: Pendiente de Git | E15: Fase 2 sin seguimiento al 21-10-2026; registrar cambios reales | F15: Equipo
A16: Aportes y exposición | B16: Integrantes identificados; tareas propuestas por responsable | C16: Sprint Backlog.xlsx; historial Git previo | D16: Por demostrar | E16: No acreditar equidad ni dominio oral sin evidencia individual y exposición | F16: Equipo
